Traceback (most recent call last):
  File "/opt/hostedtoolcache/Python/3.10.8/x64/lib/python3.10/site-packages/jupyter_cache/executors/utils.py", line 51, in single_nb_execution
    executenb(
  File "/opt/hostedtoolcache/Python/3.10.8/x64/lib/python3.10/site-packages/nbclient/client.py", line 1204, in execute
    return NotebookClient(nb=nb, resources=resources, km=km, **kwargs).execute()
  File "/opt/hostedtoolcache/Python/3.10.8/x64/lib/python3.10/site-packages/nbclient/util.py", line 84, in wrapped
    return just_run(coro(*args, **kwargs))
  File "/opt/hostedtoolcache/Python/3.10.8/x64/lib/python3.10/site-packages/nbclient/util.py", line 62, in just_run
    return loop.run_until_complete(coro)
  File "/opt/hostedtoolcache/Python/3.10.8/x64/lib/python3.10/asyncio/base_events.py", line 649, in run_until_complete
    return future.result()
  File "/opt/hostedtoolcache/Python/3.10.8/x64/lib/python3.10/site-packages/nbclient/client.py", line 663, in async_execute
    await self.async_execute_cell(
  File "/opt/hostedtoolcache/Python/3.10.8/x64/lib/python3.10/site-packages/nbclient/client.py", line 965, in async_execute_cell
    await self._check_raise_for_error(cell, cell_index, exec_reply)
  File "/opt/hostedtoolcache/Python/3.10.8/x64/lib/python3.10/site-packages/nbclient/client.py", line 862, in _check_raise_for_error
    raise CellExecutionError.from_cell_and_msg(cell, exec_reply_content)
nbclient.exceptions.CellExecutionError: An error occurred while executing the following cell:
------------------
from annotutils import database

connection = database.get_database_connection()
n_annotations = connection.execute(
    "select count(*) as n_annotations from annotation"
).fetchone()["n_annotations"]

print(f"There are {n_annotations} annotations in the database.")
------------------

[0;31m---------------------------------------------------------------------------[0m
[0;31mTypeError[0m                                 Traceback (most recent call last)
Cell [0;32mIn [1], line 4[0m
[1;32m      1[0m [38;5;28;01mfrom[39;00m [38;5;21;01mannotutils[39;00m [38;5;28;01mimport[39;00m database
[1;32m      3[0m connection [38;5;241m=[39m database[38;5;241m.[39mget_database_connection()
[0;32m----> 4[0m n_annotations [38;5;241m=[39m [43mconnection[49m[38;5;241;43m.[39;49m[43mexecute[49m[43m([49m
[1;32m      5[0m [43m    [49m[38;5;124;43m"[39;49m[38;5;124;43mselect count(*) as n_annotations from annotation[39;49m[38;5;124;43m"[39;49m
[1;32m      6[0m [43m)[49m[38;5;241;43m.[39;49m[43mfetchone[49m[43m([49m[43m)[49m[43m[[49m[38;5;124;43m"[39;49m[38;5;124;43mn_annotations[39;49m[38;5;124;43m"[39;49m[43m][49m
[1;32m      8[0m [38;5;28mprint[39m([38;5;124mf[39m[38;5;124m"[39m[38;5;124mThere are [39m[38;5;132;01m{[39;00mn_annotations[38;5;132;01m}[39;00m[38;5;124m annotations in the database.[39m[38;5;124m"[39m)

[0;31mTypeError[0m: tuple indices must be integers or slices, not str
TypeError: tuple indices must be integers or slices, not str

